<?xml version="1.0"?>
<robot xmlns:xacro="http://www.ros.org/wiki/xacro" >
  
    <xacro:include filename="inertial_macros.xacro"/>

    <material name="white">
        <color rgba="1 1 1 1" />
    </material>

    <material name="orange">
        <color rgba="1 0.3 0.1 1"/>
    </material>

    <material name="blue">
        <color rgba="0.2 0.2 1 1"/>
    </material>

    <material name="black">
        <color rgba="0 0 0 1"/>
    </material>  
    <!-- Base link -->
    <link name="base_link">

    </link>
    <!-- Chassis link -->
    <joint name="chassis_joint" type="fixed">
        <parent link="base_link"/>
        <child link="chassis_link"/>
        <origin xyz="0 0 0"/>
    </joint>
    <link name="chassis_link">
      <visual>
        <origin xyz="0 0 0" rpy="0 0 0" />
        <geometry>
          <mesh
            filename="package://my_bot/meshes/base_link.STL" />
        </geometry>
      </visual>
      <collision>
        <origin xyz="0 0 0" rpy="0 0 0" />
        <geometry>
          <mesh
            filename="package://my_bot/meshes/base_link.STL" />
        </geometry>
      </collision>
      <xacro:inertial_box mass="1.3" x="0.15" y="0.25" z="0.8">
            <origin xyz="0 0 0" rpy="0 0 0"/>
      </xacro:inertial_box>
    </link>
    <gazebo reference="chassis_link">
      <material>Gazebo/Pioneer2Body</material>
    </gazebo>

    <!-- left wheel link -->
    <joint name="left_wheel_joint" type="continuous">
      <origin
        xyz="-0.0710151540662201 -0.0910000000000003 -0.0417600000000003"
        rpy="-1.5707963267949 0 0" />
      <parent
        link="base_link" />
      <child
        link="left_wheel_link" />
      <axis
        xyz="-0.000109890109227877 0 0.999999993962082" />
    </joint>

    <link name="left_wheel_link">
      <visual>
      <geometry>
        <mesh
          filename="package://my_bot/meshes/left_wheel_link.STL" />
      </geometry>
      </visual>   
      <collision>
        <geometry>
          <mesh
            filename="package://my_bot/meshes/left_wheel_link.STL" />
        </geometry>
      </collision>
      <xacro:inertial_cylinder mass="0.8" length="0.03" radius="0.065">
            <origin xyz="0 0 0" rpy="0 0 0"/>
      </xacro:inertial_cylinder>
    </link>
    <gazebo reference="left_wheel_link">
      <material>Gazebo/Gray</material>
    </gazebo>

    <!-- right wheel link -->
    <joint name="right_wheel_joint" type="continuous">
      <origin
        xyz="-0.0710351540662204 0.0910000000000001 -0.0417600000000005"
        rpy="-1.5707963267949 0 0" />
      <parent
        link="base_link" />
      <child
        link="right_wheel_link" />
      <axis
        xyz="-0.000109890109227877 0 0.999999993962082" />
    </joint>
    <link name="right_wheel_link">
      <visual>
        <origin
          xyz="0 0 0"
          rpy="0 0 0" />
        <geometry>
          <mesh
            filename="package://my_bot/meshes/right_wheel_link.STL" />
        </geometry>
      </visual>
      <collision>
        <origin
          xyz="0 0 0"
          rpy="0 0 0" />
        <geometry>
          <mesh
            filename="package://my_bot/meshes/right_wheel_link.STL" />
        </geometry>
      </collision>
      <xacro:inertial_cylinder mass="0.8" length="0.03" radius="0.065">
        <origin xyz="0 0 0" rpy="0 0 0"/>
      </xacro:inertial_cylinder>
    </link>
    <gazebo reference="right_wheel_link">
      <material>Gazebo/Gray</material>
    </gazebo>

    <!-- base caster link -->
    <joint name="base_caster_joint" type="continuous">
      <origin
        xyz="0.0909748459337795 0 -0.0484999999999999"
        rpy="0 0 0" />
      <parent
        link="base_link" />
      <child
        link="base_caster_link" />
      <axis
        xyz="0 0 -1" />
    </joint>
    <link name="base_caster_link">
      <inertial>
        <origin
          xyz="-0.0065484535252593 -0.00020809110351333 -0.00577858701291478"
          rpy="0 0 0" />
        <mass
          value="0.0161823654839401" />
        <inertia
          ixx="0.000001"
          ixy="0"
          ixz="-0.000003"
          iyy="0.0000001"
          iyz="0"
          izz="0.0000002" />
      </inertial>
      <visual>
        <origin
          xyz="0 0 0"
          rpy="0 0 0" />
        <geometry>
          <mesh
            filename="package://my_bot/meshes/base_caster_link.STL" />
        </geometry>
      </visual>
      <collision>
        <origin
          xyz="0 0 0"
          rpy="0 0 0" />
        <geometry>
          <mesh
            filename="package://my_bot/meshes/base_caster_link.STL" />
        </geometry>
      </collision>
    </link>
    <gazebo reference="base_caster_link">
      <material>Gazebo/Gray</material>
    </gazebo>
    <!-- wheel caster link -->
    <joint name="wheel_caster_joint" type="continuous">
      <origin
        xyz="-0.0150142056791568 -0.000141668664297767 -0.0164601469749998"
        rpy="0 0 0" />
      <parent
        link="base_caster_link" />
      <child
        link="wheel_caster_link" />
      <axis
        xyz="-0.0094352216341657 0.999955487305667 0" />
    </joint>
    <link name="wheel_caster_link">
      <visual>
        <origin
          xyz="0 0 0"
          rpy="0 0 0" />
        <geometry>
          <mesh
            filename="package://my_bot/meshes/wheel_caster_link.STL" />
        </geometry>
      </visual>
      <collision>
        <origin
          xyz="0 0 0"
          rpy="0 0 0" />
        <geometry>
          <mesh
            filename="package://my_bot/meshes/wheel_caster_link.STL" />
        </geometry>
      </collision>
      <xacro:inertial_cylinder mass="0.08" length="0.02" radius="0.025">
            <origin xyz="0 0 0" rpy="0 0 0"/>
      </xacro:inertial_cylinder>
    </link>
    <gazebo reference="wheel_caster_link">
      <material>Gazebo/Gray</material>
    </gazebo>
</robot>